Workbook

Sheet Analyst 260421 BL
B1: Sample Name | C1: Ergothioneine_1
B2: 0.095_ppb | C2: < 0
B3: 0.19_ppb | C3: < 0
B4: 0.39_ppb | C4: < 0
B5: 0.78_ppb | C5: 0.253
B6: 1.56_ppb | C6: 0.875
B7: 3.125_ppb | C7: 2.23
B8: 6.25_ppb | C8: 5.87
B9: 12.5_ppb | C9: 11.6
B10: 25_ppb | C10: 22.4
B11: 50_ppb | C11: 46.2
B12: 100_ppb | C12: 96.1
B13: 200_ppb | C13: 190
B14: 400_ppb | C14: 400
B15: 800_ppb | C15: 820
B16: Blank | C16: N/A
B17: 1_26-0603_10X | C17: 32.4
B18: 2_26-0612_10X | C18: 25.9
B19: 3_26-0610_10X | C19: 16.7
B20: 4_26-0598_10X | C20: 23.9
B21: 5_26-0611_10X | C21: 32.1
B22: 6_26-0609_10X | C22: 30.2
B23: Blank | C23: N/A
B24: 25_ppb | C24: 22.5
B25: 7_26-0604_10X | C25: 63.5
B26: 8_26-0607_10X | C26: 25.9
B27: 9_26-0599_10X | C27: 36.9
B28: 10_26-0602_10X | C28: 25.1
B29: 11_26-0613_10X | C29: 25.6
B30: 12_26-0601_10X | C30: 83.9
B31: Blank | C31: N/A
B32: 25_ppb | C32: 21.6
B33: 13_26-0608_10X | C33: 30.4
B34: 14_26-0606_10X | C34: 31.4
B35: 15_26-0605_10X | C35: 38.1
B36: 16_26-0600_10X | C36: 22.4
B37: 17_26-0616_10X | C37: 19.1
B38: 18_26-0645_10X | C38: 17.8
B39: Blank | C39: N/A
B40: 25_ppb | C40: 19.6
...

Sheet gina
M1: L-(+)-Ergothioneine
B2: Reg no. | C2: ben_sample_nu | D2: loc_au | E2: loc_id | F2: plot_id | G2: trt_id | H2: plot_half | I2: g sample | K2: Dilut | L2: Ml ekst. | M2: ng/ml | N2: µg/g
A3: 1 | B3: 26-0603 | C3: 6 | D3: flakkebjerg | E3: sexy1 | F3: 202 | G3: a | H3: Y | I3: 0.025 | K3: 10 | L3: 2 | M3: ='Analyst 260421 BL'!C17 -> 32.4 | N3: =M3*K3*L3/(I3*1000) -> 25.92
A4: 2 | B4: 26-0612 | C4: 15 | D4: flakkebjerg | E4: sexy1 | F4: 412 | G4: a | H4: D | I4: 0.025 | K4: 10 | L4: 2 | M4: ='Analyst 260421 BL'!C18 -> 25.9 | N4: =(M4*K4*L4)/(I4*1000) -> 20.72
A5: 3 | B5: 26-0610 | C5: 13 | D5: flakkebjerg | E5: sexy1 | F5: 405 | G5: p | H5: D | I5: 0.0249 | K5: 10 | L5: 2 | M5: ='Analyst 260421 BL'!C19 -> 16.7 | N5: =(M5*K5*L5)/(I5*1000) -> 13.413655
A6: 4 | B6: 26-0598 | C6: 1 | D6: flakkebjerg | E6: sexy1 | F6: 101 | G6: p | H6: D | I6: 0.0248 | K6: 10 | L6: 2 | M6: ='Analyst 260421 BL'!C20 -> 23.9 | N6: =(M6*K6*L6)/(I6*1000) -> 19.274194
A7: 5 | B7: 26-0611 | C7: 14 | D7: flakkebjerg | E7: sexy1 | F7: 405 | G7: p | H7: Y | I7: 0.025 | K7: 10 | L7: 2 | M7: ='Analyst 260421 BL'!C21 -> 32.1 | N7: =(M7*K7*L7)/(I7*1000) -> 25.68
A8: 6 | B8: 26-0609 | C8: 12 | D8: flakkebjerg | E8: sexy1 | F8: 311 | G8: p | H8: Y | I8: 0.0257 | K8: 10 | L8: 2 | M8: ='Analyst 260421 BL'!C22 -> 30.2 | N8: =(M8*K8*L8)/(I8*1000) -> 23.501946
A9: 7 | B9: 26-0604 | C9: 7 | D9: flakkebjerg | E9: sexy1 | F9: 209 | G9: p | H9: D | I9: 0.0255 | K9: 10 | L9: 2 | M9: ='Analyst 260421 BL'!C25 -> 63.5 | N9: =(M9*K9*L9)/(I9*1000) -> 49.803922
A10: 8 | B10: 26-0607 | C10: 10 | D10: flakkebjerg | E10: sexy1 | F10: 307 | G10: a | H10: Y | I10: 0.0255 | K10: 10 | L10: 2 | M10: ='Analyst 260421 BL'!C26 -> 25.9 | N10: =(M10*K10*L10)/(I10*1000) -> 20.313725
A11: 9 | B11: 26-0599 | C11: 2 | D11: flakkebjerg | E11: sexy1 | F11: 101 | G11: p | H11: Y | I11: 0.0245 | K11: 10 | L11: 2 | M11: ='Analyst 260421 BL'!C27 -> 36.9 | N11: =(M11*K11*L11)/(I11*1000) -> 30.122449
A12: 10 | B12: 26-0602 | C12: 5 | D12: flakkebjerg | E12: sexy1 | F12: 202 | G12: a | H12: D | I12: 0.0245 | K12: 10 | L12: 2 | M12: ='Analyst 260421 BL'!C28 -> 25.1 | N12: =(M12*K12*L12)/(I12*1000) -> 20.489796
A13: 11 | B13: 26-0613 | C13: 16 | D13: flakkebjerg | E13: sexy1 | F13: 412 | G13: a | H13: Y | I13: 0.0247 | K13: 10 | L13: 2 | M13: ='Analyst 260421 BL'!C29 -> 25.6 | N13: =(M13*K13*L13)/(I13*1000) -> 20.728745
A14: 12 | B14: 26-0601 | C14: 4 | D14: flakkebjerg | E14: sexy1 | F14: 105 | G14: a | H14: Y | I14: 0.0248 | K14: 10 | L14: 2 | M14: ='Analyst 260421 BL'!C30 -> 83.9 | N14: =(M14*K14*L14)/(I14*1000) -> 67.66129
A15: 13 | B15: 26-0608 | C15: 11 | D15: flakkebjerg | E15: sexy1 | F15: 311 | G15: p | H15: D | I15: 0.0254 | K15: 10 | L15: 2 | M15: ='Analyst 260421 BL'!C33 -> 30.4 | N15: =(M15*K15*L15)/(I15*1000) -> 23.937008
A16: 14 | B16: 26-0606 | C16: 9 | D16: flakkebjerg | E16: sexy1 | F16: 307 | G16: a | H16: D | I16: 0.0259 | K16: 10 | L16: 2 | M16: ='Analyst 260421 BL'!C34 -> 31.4 | N16: =(M16*K16*L16)/(I16*1000) -> 24.247104
A17: 15 | B17: 26-0605 | C17: 8 | D17: flakkebjerg | E17: sexy1 | F17: 209 | G17: p | H17: Y | I17: 0.0248 | K17: 10 | L17: 2 | M17: ='Analyst 260421 BL'!C35 -> 38.1 | N17: =(M17*K17*L17)/(I17*1000) -> 30.725806
A18: 16 | B18: 26-0600 | C18: 3 | D18: flakkebjerg | E18: sexy1 | F18: 105 | G18: a | H18: D | I18: 0.0247 | K18: 10 | L18: 2 | M18: ='Analyst 260421 BL'!C36 -> 22.4 | N18: =(M18*K18*L18)/(I18*1000) -> 18.137652

Sheet gina  final
L1: L-(+)-Ergothioneine
B2: Reg no. | C2: ben_sample_nu | D2: loc_au | E2: loc_id | F2: plot_id | G2: trt_id | H2: plot_half | I2: g sample | J2: Dilut | K2: Ml ekst. | L2: ng/ml | M2: µg/g
A3: 4 | B3: 26-0598 | C3: 1 | D3: flakkebjerg | E3: sexy1 | F3: 101 | G3: p | H3: D | I3: 0.0248 | J3: 10 | K3: 2 | L3: ='Analyst 260421 BL'!C20 -> 23.9 | M3: =(L3*J3*K3)/(I3*1000) -> 19.274194
A4: 9 | B4: 26-0599 | C4: 2 | D4: flakkebjerg | E4: sexy1 | F4: 101 | G4: p | H4: Y | I4: 0.0245 | J4: 10 | K4: 2 | L4: ='Analyst 260421 BL'!C27 -> 36.9 | M4: =(L4*J4*K4)/(I4*1000) -> 30.122449
A5: 16 | B5: 26-0600 | C5: 3 | D5: flakkebjerg | E5: sexy1 | F5: 105 | G5: a | H5: D | I5: 0.0247 | J5: 10 | K5: 2 | L5: ='Analyst 260421 BL'!C36 -> 22.4 | M5: =(L5*J5*K5)/(I5*1000) -> 18.137652
A6: 12 | B6: 26-0601 | C6: 4 | D6: flakkebjerg | E6: sexy1 | F6: 105 | G6: a | H6: Y | I6: 0.0248 | J6: 10 | K6: 2 | L6: ='Analyst 260421 BL'!C30 -> 83.9 | M6: =(L6*J6*K6)/(I6*1000) -> 67.66129
A7: 10 | B7: 26-0602 | C7: 5 | D7: flakkebjerg | E7: sexy1 | F7: 202 | G7: a | H7: D | I7: 0.0245 | J7: 10 | K7: 2 | L7: ='Analyst 260421 BL'!C28 -> 25.1 | M7: =(L7*J7*K7)/(I7*1000) -> 20.489796
A8: 1 | B8: 26-0603 | C8: 6 | D8: flakkebjerg | E8: sexy1 | F8: 202 | G8: a | H8: Y | I8: 0.025 | J8: 10 | K8: 2 | L8: ='Analyst 260421 BL'!C17 -> 32.4 | M8: =L8*J8*K8/(I8*1000) -> 25.92
A9: 7 | B9: 26-0604 | C9: 7 | D9: flakkebjerg | E9: sexy1 | F9: 209 | G9: p | H9: D | I9: 0.0255 | J9: 10 | K9: 2 | L9: ='Analyst 260421 BL'!C25 -> 63.5 | M9: =(L9*J9*K9)/(I9*1000) -> 49.803922
A10: 15 | B10: 26-0605 | C10: 8 | D10: flakkebjerg | E10: sexy1 | F10: 209 | G10: p | H10: Y | I10: 0.0248 | J10: 10 | K10: 2 | L10: ='Analyst 260421 BL'!C35 -> 38.1 | M10: =(L10*J10*K10)/(I10*1000) -> 30.725806
A11: 14 | B11: 26-0606 | C11: 9 | D11: flakkebjerg | E11: sexy1 | F11: 307 | G11: a | H11: D | I11: 0.0259 | J11: 10 | K11: 2 | L11: ='Analyst 260421 BL'!C34 -> 31.4 | M11: =(L11*J11*K11)/(I11*1000) -> 24.247104
A12: 8 | B12: 26-0607 | C12: 10 | D12: flakkebjerg | E12: sexy1 | F12: 307 | G12: a | H12: Y | I12: 0.0255 | J12: 10 | K12: 2 | L12: ='Analyst 260421 BL'!C26 -> 25.9 | M12: =(L12*J12*K12)/(I12*1000) -> 20.313725
A13: 13 | B13: 26-0608 | C13: 11 | D13: flakkebjerg | E13: sexy1 | F13: 311 | G13: p | H13: D | I13: 0.0254 | J13: 10 | K13: 2 | L13: ='Analyst 260421 BL'!C33 -> 30.4 | M13: =(L13*J13*K13)/(I13*1000) -> 23.937008
A14: 6 | B14: 26-0609 | C14: 12 | D14: flakkebjerg | E14: sexy1 | F14: 311 | G14: p | H14: Y | I14: 0.0257 | J14: 10 | K14: 2 | L14: ='Analyst 260421 BL'!C22 -> 30.2 | M14: =(L14*J14*K14)/(I14*1000) -> 23.501946
A15: 3 | B15: 26-0610 | C15: 13 | D15: flakkebjerg | E15: sexy1 | F15: 405 | G15: p | H15: D | I15: 0.0249 | J15: 10 | K15: 2 | L15: ='Analyst 260421 BL'!C19 -> 16.7 | M15: =(L15*J15*K15)/(I15*1000) -> 13.413655
A16: 5 | B16: 26-0611 | C16: 14 | D16: flakkebjerg | E16: sexy1 | F16: 405 | G16: p | H16: Y | I16: 0.025 | J16: 10 | K16: 2 | L16: ='Analyst 260421 BL'!C21 -> 32.1 | M16: =(L16*J16*K16)/(I16*1000) -> 25.68
A17: 2 | B17: 26-0612 | C17: 15 | D17: flakkebjerg | E17: sexy1 | F17: 412 | G17: a | H17: D | I17: 0.025 | J17: 10 | K17: 2 | L17: ='Analyst 260421 BL'!C18 -> 25.9 | M17: =(L17*J17*K17)/(I17*1000) -> 20.72
A18: 11 | B18: 26-0613 | C18: 16 | D18: flakkebjerg | E18: sexy1 | F18: 412 | G18: a | H18: Y | I18: 0.0247 | J18: 10 | K18: 2 | L18: ='Analyst 260421 BL'!C29 -> 25.6 | M18: =(L18*J18*K18)/(I18*1000) -> 20.728745

Sheet Ark1
B1: Reg no. | C1: fort | E1: etiket
A2: 1 | B2: 26-0603 | C2: 10X | D2: _ | E2: =_xlfn.CONCAT(A2,D2,B2,D2,C2) -> 1_26-0603_10X
A3: 2 | B3: 26-0612 | C3: 10X | D3: _ | E3: =_xlfn.CONCAT(A3,D3,B3,D3,C3) -> 2_26-0612_10X
A4: 3 | B4: 26-0610 | C4: 10X | D4: _ | E4: =_xlfn.CONCAT(A4,D4,B4,D4,C4) -> 3_26-0610_10X
A5: 4 | B5: 26-0598 | C5: 10X | D5: _ | E5: =_xlfn.CONCAT(A5,D5,B5,D5,C5) -> 4_26-0598_10X
A6: 5 | B6: 26-0611 | C6: 10X | D6: _ | E6: =_xlfn.CONCAT(A6,D6,B6,D6,C6) -> 5_26-0611_10X
A7: 6 | B7: 26-0609 | C7: 10X | D7: _ | E7: =_xlfn.CONCAT(A7,D7,B7,D7,C7) -> 6_26-0609_10X
A8: 7 | B8: 26-0604 | C8: 10X | D8: _ | E8: =_xlfn.CONCAT(A8,D8,B8,D8,C8) -> 7_26-0604_10X
A9: 8 | B9: 26-0607 | C9: 10X | D9: _ | E9: =_xlfn.CONCAT(A9,D9,B9,D9,C9) -> 8_26-0607_10X
A10: 9 | B10: 26-0599 | C10: 10X | D10: _ | E10: =_xlfn.CONCAT(A10,D10,B10,D10,C10) -> 9_26-0599_10X
A11: 10 | B11: 26-0602 | C11: 10X | D11: _ | E11: =_xlfn.CONCAT(A11,D11,B11,D11,C11) -> 10_26-0602_10X
A12: 11 | B12: 26-0613 | C12: 10X | D12: _ | E12: =_xlfn.CONCAT(A12,D12,B12,D12,C12) -> 11_26-0613_10X
A13: 12 | B13: 26-0601 | C13: 10X | D13: _ | E13: =_xlfn.CONCAT(A13,D13,B13,D13,C13) -> 12_26-0601_10X
... A17: 16 | B17: 26-0600 | C17: 10X | D17: _ | E17: =_xlfn.CONCAT(A17,D17,B17,D17,C17) -> 16_26-0600_10X
B18: Reg no. | C18: 10X | D18: _ | E18: =_xlfn.CONCAT(A18,D18,B18,D18,C18) -> _Reg no._10X
A19: 17 | B19: 26-0616 | C19: 10X | D19: _ | E19: =_xlfn.CONCAT(A19,D19,B19,D19,C19) -> 17_26-0616_10X
A20: 18 | B20: 26-0645 | C20: 10X | D20: _ | E20: =_xlfn.CONCAT(A20,D20,B20,D20,C20) -> 18_26-0645_10X
A21: 19 | B21: 26-0626 | C21: 10X | D21: _ | E21: =_xlfn.CONCAT(A21,D21,B21,D21,C21) -> 19_26-0626_10X
A22: 20 | B22: 26-0617 | C22: 10X | D22: _ | E22: =_xlfn.CONCAT(A22,D22,B22,D22,C22) -> 20_26-0617_10X
A23: 21 | B23: 26-0639 | C23: 10X | D23: _ | E23: =_xlfn.CONCAT(A23,D23,B23,D23,C23) -> 21_26-0639_10X
A24: 22 | B24: 26-0636 | C24: 10X | D24: _ | E24: =_xlfn.CONCAT(A24,D24,B24,D24,C24) -> 22_26-0636_10X
A25: 23 | B25: 26-0635 | C25: 10X | D25: _ | E25: =_xlfn.CONCAT(A25,D25,B25,D25,C25) -> 23_26-0635_10X
A26: 24 | B26: 26-0618 | C26: 10X | D26: _ | E26: =_xlfn.CONCAT(A26,D26,B26,D26,C26) -> 24_26-0618_10X
A27: 25 | B27: 26-0627 | C27: 10X | D27: _ | E27: =_xlfn.CONCAT(A27,D27,B27,D27,C27) -> 25_26-0627_10X
A28: 26 | B28: 26-0638 | C28: 10X | D28: _ | E28: =_xlfn.CONCAT(A28,D28,B28,D28,C28) -> 26_26-0638_10X
A29: 27 | B29: 26-0632 | C29: 10X | D29: _ | E29: =_xlfn.CONCAT(A29,D29,B29,D29,C29) -> 27_26-0632_10X
A30: 28 | B30: 26-0621 | C30: 10X | D30: _ | E30: =_xlfn.CONCAT(A30,D30,B30,D30,C30) -> 28_26-0621_10X
... A50: 48 | B50: 26-0633 | C50: 10X | D50: _ | E50: =_xlfn.CONCAT(A50,D50,B50,D50,C50) -> 48_26-0633_10X
